Workbook

Sheet Assumptions
A1: Scenario 1: Tăng chi phí đầu tư vào S&M và giảm OTA
A3: Operating Drivers | B3: Jan | C3: Feb | D3: Mar | E3: Apr | F3: May | G3: Jun | H3: Jul | I3: Aug | J3: Sep | K3: Oct | L3: Nov | M3: Dec | N3: YTD / Annual
A4: Total Keys | B4: 150 | C4: 150 | D4: 150 | E4: 150 | F4: 150 | G4: 150 | H4: 150 | I4: 150 | J4: 150 | K4: 150 | L4: 150 | M4: 150 | N4: =B4 -> 150
A5: Days per Month | B5: 30 | C5: 30 | D5: 30 | E5: 30 | F5: 30 | G5: 30 | H5: 30 | I5: 30 | J5: 30 | K5: 30 | L5: 30 | M5: 30 | N5: =SUM(B5:M5) -> 360
A6: Occupancy | B6: 0.75 | C6: 0.72 | D6: 0.66 | E6: 0.64 | F6: 0.52 | G6: 0.62 | H6: 0.75 | I6: 0.73 | J6: 0.52 | K6: 0.55 | L6: 0.68 | M6: 0.66 | N6: =AVERAGE(B6:M6) -> 0.65
A7: ADR ($) | B7: 269.05 | C7: 264.16 | D7: 244.59 | E7: 239.7 | F7: 220.13 | G7: 239.7 | H7: 269.05 | I7: 264.16 | J7: 220.13 | K7: 225.03 | L7: 249.49 | M7: 269.05 | N7: =SUMPRODUCT(B6:M6,B7:M7)/SUM(B6:M6) -> 249.99824
A9: Context: Tăng đầu tư S&M để giảm phụ thuộc vào kênh OTA ( Tăng S&M từ 8%-> 9%, giảm Room Commissions từ 3% -> 1%)
A10: Assumption | B10: Baseline | C10: Formula / Meaning | D10: Source / Note
A11: F&B Revenue / Rooms Revenue | B11: 0.4 | C11: F&B Revenue = Rooms Revenue × % | D11: User-provided prompt
A12: Spa/Other Revenue / Rooms Revenue | B12: 0.1 | C12: Other Operated Dept Revenue = Rooms Revenue × % | D12: User-provided prompt
A13: Rooms Payroll & Related / Rooms Rev | B13: 0.14 | C13: Rooms Payroll = Rooms Revenue × % | D13: Model baseline within requested 75%–78% Rooms profit margin
A14: Rooms Commissions / Rooms Rev | B14: 0.01 | C14: Non-OTA commissions = Rooms Revenue × % | D14: Model baseline; OTA/brand marketing kept in S&M per user assumption
A15: Rooms Other OpEx / Rooms Rev | B15: 0.06 | C15: Rooms Other OpEx = Rooms Revenue × % | D15: Model baseline
A16: F&B COGS / F&B Rev | B16: 0.3 | C16: F&B COGS = F&B Revenue × % | D16: User requested approx. 30%
A17: F&B Payroll & Related / F&B Rev | B17: 0.35 | C17: F&B Payroll = F&B Revenue × % | D17: User requested approx. 35%
A18: F&B Other OpEx / F&B Rev | B18: 0.125 | C18: F&B Other OpEx = F&B Revenue × % | D18: Sets F&B departmental profit margin to 22.5%
A19: Spa/Other Payroll / Other Rev | B19: 0.4 | C19: Spa/Other Payroll = Other Revenue × % | D19: Model baseline
A20: Spa/Other Other OpEx / Other Rev | B20: 0.225 | C20: Spa/Other Other OpEx = Other Revenue × % | D20: Sets Other Dept profit margin to 37.5%
A21: A&G / Total Operating Revenue | B21: 0.09 | C21: A&G = Total Operating Revenue × % | D21: Within requested 8%–10%
A22: IT&S / Total Operating Revenue | B22: 0.015 | C22: IT&S = Total Operating Revenue × % | D22: Added for USALI 11 completeness; HFTP lists IT&S as an undistributed department
... A28: FF&E Reserve / Total Revenue | B28: 0.04 | C28: FF&E Reserve = Total Operating Revenue × % | D28: User-provided prompt

Sheet Pro Forma P&L
A1: Scenario 1: Tăng chi phí đầu tư vào S&M và giảm OTA
A3: Line Item | B3: Jan | C3: Feb | D3: Mar | E3: Apr | F3: May | G3: Jun | H3: Jul | I3: Aug | J3: Sep | K3: Oct | L3: Nov | M3: Dec | N3: YTD / Annual
A4: Available Rooms | B4: =Assumptions!B$4*Assumptions!B$5 -> 4500 | C4: =Assumptions!C$4*Assumptions!C$5 -> 4500 | D4: =Assumptions!D$4*Assumptions!D$5 -> 4500 | E4: =Assumptions!E$4*Assumptions!E$5 -> 4500 | F4: =Assumptions!F$4*Assumptions!F$5 -> 4500 | G4: =Assumptions!G$4*Assumptions!G$5 -> 4500 | H4: =Assumptions!H$4*Assumptions!H$5 -> 4500 | I4: =Assumptions!I$4*Assumptions!I$5 -> 4500 | ... M4: =Assumptions!M$4*Assumptions!M$5 -> 4500 | N4: =SUM(B4:M4) -> 54000
A5: Occupancy | B5: =Assumptions!B$6 -> 0.75 | C5: =Assumptions!C$6 -> 0.72 | D5: =Assumptions!D$6 -> 0.66 | E5: =Assumptions!E$6 -> 0.64 | F5: =Assumptions!F$6 -> 0.52 | G5: =Assumptions!G$6 -> 0.62 | H5: =Assumptions!H$6 -> 0.75 | I5: =Assumptions!I$6 -> 0.73 | ... M5: =Assumptions!M$6 -> 0.66 | N5: =N6/N4 -> 0.65
A6: Rooms Sold | B6: =B4*B5 -> 3375 | C6: =C4*C5 -> 3240 | D6: =D4*D5 -> 2970 | E6: =E4*E5 -> 2880 | F6: =F4*F5 -> 2340 | G6: =G4*G5 -> 2790 | H6: =H4*H5 -> 3375 | I6: =I4*I5 -> 3285 | ... M6: =M4*M5 -> 2970 | N6: =SUM(B6:M6) -> 35100
A7: ADR | B7: =Assumptions!B$7 -> 269.05 | C7: =Assumptions!C$7 -> 264.16 | D7: =Assumptions!D$7 -> 244.59 | E7: =Assumptions!E$7 -> 239.7 | F7: =Assumptions!F$7 -> 220.13 | G7: =Assumptions!G$7 -> 239.7 | H7: =Assumptions!H$7 -> 269.05 | I7: =Assumptions!I$7 -> 264.16 | ... M7: =Assumptions!M$7 -> 269.05 | N7: =N10/N6 -> 249.99824
A9: OPERATING REVENUE
A10: Rooms Revenue | B10: =B6*B7 -> 908043.75 | C10: =C6*C7 -> 855878.4 | D10: =D6*D7 -> 726432.3 | E10: =E6*E7 -> 690336 | F10: =F6*F7 -> 515104.2 | G10: =G6*G7 -> 668763 | H10: =H6*H7 -> 908043.75 | I10: =I6*I7 -> 867765.6 | ... M10: =M6*M7 -> 799078.5 | N10: =SUM(B10:M10) -> 8774938.4
A11: Food & Beverage Revenue | B11: =B10*Assumptions!$B$11 -> 363217.5 | C11: =C10*Assumptions!$B$11 -> 342351.36 | D11: =D10*Assumptions!$B$11 -> 290572.92 | E11: =E10*Assumptions!$B$11 -> 276134.4 | F11: =F10*Assumptions!$B$11 -> 206041.68 | G11: =G10*Assumptions!$B$11 -> 267505.2 | H11: =H10*Assumptions!$B$11 -> 363217.5 | I11: =I10*Assumptions!$B$11 -> 347106.24 | ... M11: =M10*Assumptions!$B$11 -> 319631.4 | N11: =SUM(B11:M11) -> 3509975.3
A12: Other Operated Departments Revenue – Spa/Minor | B12: =B10*Assumptions!$B$12 -> 90804.375 | C12: =C10*Assumptions!$B$12 -> 85587.84 | D12: =D10*Assumptions!$B$12 -> 72643.23 | E12: =E10*Assumptions!$B$12 -> 69033.6 | F12: =F10*Assumptions!$B$12 -> 51510.42 | G12: =G10*Assumptions!$B$12 -> 66876.3 | H12: =H10*Assumptions!$B$12 -> 90804.375 | I12: =I10*Assumptions!$B$12 -> 86776.56 | ... M12: =M10*Assumptions!$B$12 -> 79907.85 | N12: =SUM(B12:M12) -> 877493.84
A13: Miscellaneous Income | B13: 0 | C13: 0 | D13: 0 | E13: 0 | F13: 0 | G13: 0 | H13: 0 | I13: 0 | J13: 0 | K13: 0 | L13: 0 | M13: 0 | N13: =SUM(B13:M13) -> 0
A14: Total Operating Revenue | B14: =SUM(B10:B13) -> 1362065.6 | C14: =SUM(C10:C13) -> 1283817.6 | D14: =SUM(D10:D13) -> 1089648.5 | E14: =SUM(E10:E13) -> 1035504 | F14: =SUM(F10:F13) -> 772656.3 | G14: =SUM(G10:G13) -> 1003144.5 | H14: =SUM(H10:H13) -> 1362065.6 | I14: =SUM(I10:I13) -> 1301648.4 | ... M14: =SUM(M10:M13) -> 1198617.8 | N14: =SUM(B14:M14) -> 13162408
A16: ROOMS DEPARTMENT
A17: Payroll & Related | B17: =B10*Assumptions!$B$13 -> 127126.13 | C17: =C10*Assumptions!$B$13 -> 119822.98 | D17: =D10*Assumptions!$B$13 -> 101700.52 | E17: =E10*Assumptions!$B$13 -> 96647.04 | F17: =F10*Assumptions!$B$13 -> 72114.588 | G17: =G10*Assumptions!$B$13 -> 93626.82 | H17: =H10*Assumptions!$B$13 -> 127126.13 | I17: =I10*Assumptions!$B$13 -> 121487.18 | ... M17: =M10*Assumptions!$B$13 -> 111870.99 | N17: =SUM(B17:M17) -> 1228491.4
A18: Commissions (non-OTA modeled) | B18: =B10*Assumptions!$B$14 -> 9080.4375 | C18: =C10*Assumptions!$B$14 -> 8558.784 | D18: =D10*Assumptions!$B$14 -> 7264.323 | E18: =E10*Assumptions!$B$14 -> 6903.36 | F18: =F10*Assumptions!$B$14 -> 5151.042 | G18: =G10*Assumptions!$B$14 -> 6687.63 | H18: =H10*Assumptions!$B$14 -> 9080.4375 | I18: =I10*Assumptions!$B$14 -> 8677.656 | ... M18: =M10*Assumptions!$B$14 -> 7990.785 | N18: =SUM(B18:M18) -> 87749.383
A19: Other Operating Expenses | B19: =B10*Assumptions!$B$15 -> 54482.625 | C19: =C10*Assumptions!$B$15 -> 51352.704 | D19: =D10*Assumptions!$B$15 -> 43585.938 | E19: =E10*Assumptions!$B$15 -> 41420.16 | F19: =F10*Assumptions!$B$15 -> 30906.252 | G19: =G10*Assumptions!$B$15 -> 40125.78 | H19: =H10*Assumptions!$B$15 -> 54482.625 | I19: =I10*Assumptions!$B$15 -> 52065.936 | ... M19: =M10*Assumptions!$B$15 -> 47944.71 | N19: =SUM(B19:M19) -> 526496.3
A20: Total Rooms Department Expenses | B20: =SUM(B17:B19) -> 190689.19 | C20: =SUM(C17:C19) -> 179734.46 | D20: =SUM(D17:D19) -> 152550.78 | E20: =SUM(E17:E19) -> 144970.56 | F20: =SUM(F17:F19) -> 108171.88 | G20: =SUM(G17:G19) -> 140440.23 | H20: =SUM(H17:H19) -> 190689.19 | I20: =SUM(I17:I19) -> 182230.78 | ... M20: =SUM(M17:M19) -> 167806.49 | N20: =SUM(B20:M20) -> 1842737.1
A21: Rooms Department Profit | B21: =B10-B20 -> 717354.56 | C21: =C10-C20 -> 676143.94 | D21: =D10-D20 -> 573881.52 | E21: =E10-E20 -> 545365.44 | F21: =F10-F20 -> 406932.32 | G21: =G10-G20 -> 528322.77 | H21: =H10-H20 -> 717354.56 | I21: =I10-I20 -> 685534.82 | ... M21: =M10-M20 -> 631272.02 | N21: =SUM(B21:M21) -> 6932201.3
A22: Rooms Department Profit Margin | B22: =B21/B10 -> 0.79 | C22: =C21/C10 -> 0.79 | D22: =D21/D10 -> 0.79 | E22: =E21/E10 -> 0.79 | F22: =F21/F10 -> 0.79 | G22: =G21/G10 -> 0.79 | H22: =H21/H10 -> 0.79 | I22: =I21/I10 -> 0.79 | ... N22: =N21/N10 -> 0.79
A24: FOOD & BEVERAGE DEPARTMENT
A25: Cost of Goods Sold | B25: =B11*Assumptions!$B$16 -> 108965.25 | C25: =C11*Assumptions!$B$16 -> 102705.41 | D25: =D11*Assumptions!$B$16 -> 87171.876 | E25: =E11*Assumptions!$B$16 -> 82840.32 | F25: =F11*Assumptions!$B$16 -> 61812.504 | G25: =G11*Assumptions!$B$16 -> 80251.56 | H25: =H11*Assumptions!$B$16 -> 108965.25 | I25: =I11*Assumptions!$B$16 -> 104131.87 | ... M25: =M11*Assumptions!$B$16 -> 95889.42 | N25: =SUM(B25:M25) -> 1052992.6
A26: Payroll & Related | B26: =B11*Assumptions!$B$17 -> 127126.12 | C26: =C11*Assumptions!$B$17 -> 119822.98 | D26: =D11*Assumptions!$B$17 -> 101700.52 | E26: =E11*Assumptions!$B$17 -> 96647.04 | F26: =F11*Assumptions!$B$17 -> 72114.588 | G26: =G11*Assumptions!$B$17 -> 93626.82 | H26: =H11*Assumptions!$B$17 -> 127126.12 | I26: =I11*Assumptions!$B$17 -> 121487.18 | ... M26: =M11*Assumptions!$B$17 -> 111870.99 | N26: =SUM(B26:M26) -> 1228491.4
A27: Other Operating Expenses | B27: =B11*Assumptions!$B$18 -> 45402.188 | C27: =C11*Assumptions!$B$18 -> 42793.92 | D27: =D11*Assumptions!$B$18 -> 36321.615 | E27: =E11*Assumptions!$B$18 -> 34516.8 | F27: =F11*Assumptions!$B$18 -> 25755.21 | G27: =G11*Assumptions!$B$18 -> 33438.15 | H27: =H11*Assumptions!$B$18 -> 45402.188 | I27: =I11*Assumptions!$B$18 -> 43388.28 | ... M27: =M11*Assumptions!$B$18 -> 39953.925 | N27: =SUM(B27:M27) -> 438746.92
A28: Total F&B Department Expenses | B28: =SUM(B25:B27) -> 281493.56 | C28: =SUM(C25:C27) -> 265322.3 | D28: =SUM(D25:D27) -> 225194.01 | E28: =SUM(E25:E27) -> 214004.16 | F28: =SUM(F25:F27) -> 159682.3 | G28: =SUM(G25:G27) -> 207316.53 | H28: =SUM(H25:H27) -> 281493.56 | I28: =SUM(I25:I27) -> 269007.34 | ... M28: =SUM(M25:M27) -> 247714.34 | N28: =SUM(B28:M28) -> 2720230.9
A29: F&B Department Profit | B29: =B11-B28 -> 81723.938 | C29: =C11-C28 -> 77029.056 | D29: =D11-D28 -> 65378.907 | E29: =E11-E28 -> 62130.24 | F29: =F11-F28 -> 46359.378 | G29: =G11-G28 -> 60188.67 | H29: =H11-H28 -> 81723.938 | I29: =I11-I28 -> 78098.904 | ... M29: =M11-M28 -> 71917.065 | N29: =SUM(B29:M29) -> 789744.45
A30: F&B Department Profit Margin | B30: =B29/B11 -> 0.225 | C30: =C29/C11 -> 0.225 | D30: =D29/D11 -> 0.225 | E30: =E29/E11 -> 0.225 | F30: =F29/F11 -> 0.225 | G30: =G29/G11 -> 0.225 | H30: =H29/H11 -> 0.225 | I30: =I29/I11 -> 0.225 | ... N30: =N29/N11 -> 0.225
A32: OTHER OPERATED DEPARTMENTS – SPA/MINOR
A33: Payroll & Related | B33: =B12*Assumptions!$B$19 -> 36321.75 | C33: =C12*Assumptions!$B$19 -> 34235.136 | D33: =D12*Assumptions!$B$19 -> 29057.292 | E33: =E12*Assumptions!$B$19 -> 27613.44 | F33: =F12*Assumptions!$B$19 -> 20604.168 | G33: =G12*Assumptions!$B$19 -> 26750.52 | H33: =H12*Assumptions!$B$19 -> 36321.75 | I33: =I12*Assumptions!$B$19 -> 34710.624 | ... M33: =M12*Assumptions!$B$19 -> 31963.14 | N33: =SUM(B33:M33) -> 350997.53
A34: Other Operating Expenses | B34: =B12*Assumptions!$B$20 -> 20430.984 | C34: =C12*Assumptions!$B$20 -> 19257.264 | D34: =D12*Assumptions!$B$20 -> 16344.727 | E34: =E12*Assumptions!$B$20 -> 15532.56 | F34: =F12*Assumptions!$B$20 -> 11589.845 | G34: =G12*Assumptions!$B$20 -> 15047.168 | H34: =H12*Assumptions!$B$20 -> 20430.984 | I34: =I12*Assumptions!$B$20 -> 19524.726 | ... M34: =M12*Assumptions!$B$20 -> 17979.266 | N34: =SUM(B34:M34) -> 197436.11
A35: Total Other Dept Expenses | B35: =SUM(B33:B34) -> 56752.734 | C35: =SUM(C33:C34) -> 53492.4 | D35: =SUM(D33:D34) -> 45402.019 | E35: =SUM(E33:E34) -> 43146 | F35: =SUM(F33:F34) -> 32194.013 | G35: =SUM(G33:G34) -> 41797.688 | H35: =SUM(H33:H34) -> 56752.734 | I35: =SUM(I33:I34) -> 54235.35 | ... M35: =SUM(M33:M34) -> 49942.406 | N35: =SUM(B35:M35) -> 548433.65
A36: Other Dept Profit | B36: =B12-B35 -> 34051.641 | C36: =C12-C35 -> 32095.44 | D36: =D12-D35 -> 27241.211 | E36: =E12-E35 -> 25887.6 | F36: =F12-F35 -> 19316.408 | G36: =G12-G35 -> 25078.612 | H36: =H12-H35 -> 34051.641 | I36: =I12-I35 -> 32541.21 | ... M36: =M12-M35 -> 29965.444 | N36: =SUM(B36:M36) -> 329060.19
A37: Other Dept Profit Margin | B37: =B36/B12 -> 0.375 | C37: =C36/C12 -> 0.375 | D37: =D36/D12 -> 0.375 | E37: =E36/E12 -> 0.375 | F37: =F36/F12 -> 0.375 | G37: =G36/G12 -> 0.375 | H37: =H36/H12 -> 0.375 | I37: =I36/I12 -> 0.375 | ... N37: =N36/N12 -> 0.375
A39: TOTAL DEPARTMENTAL
A40: Total Departmental Expenses | B40: =B20+B28+B35 -> 528935.48 | C40: =C20+C28+C35 -> 498549.17 | D40: =D20+D28+D35 -> 423146.81 | E40: =E20+E28+E35 -> 402120.72 | F40: =F20+F28+F35 -> 300048.2 | G40: =G20+G28+G35 -> 389554.45 | H40: =H20+H28+H35 -> 528935.48 | I40: =I20+I28+I35 -> 505473.46 | ... M40: =M20+M28+M35 -> 465463.23 | N40: =SUM(B40:M40) -> 5111401.6
A41: Total Departmental Profit | B41: =B14-B40 -> 833130.14 | C41: =C14-C40 -> 785268.43 | D41: =D14-D40 -> 666501.64 | E41: =E14-E40 -> 633383.28 | F41: =F14-F40 -> 472608.1 | G41: =G14-G40 -> 613590.05 | H41: =H14-H40 -> 833130.14 | I41: =I14-I40 -> 796174.94 | ... M41: =M14-M40 -> 733154.52 | N41: =SUM(B41:M41) -> 8051005.9
A42: Total Departmental Profit Margin | B42: =B41/B14 -> 0.61166667 | C42: =C41/C14 -> 0.61166667 | D42: =D41/D14 -> 0.61166667 | E42: =E41/E14 -> 0.61166667 | F42: =F41/F14 -> 0.61166667 | G42: =G41/G14 -> 0.61166667 | H42: =H41/H14 -> 0.61166667 | I42: =I41/I14 -> 0.61166667 | ... N42: =N41/N14 -> 0.61166667
A44: UNDISTRIBUTED OPERATING EXPENSES
A45: Administrative & General (A&G) | B45: =B14*Assumptions!$B$21 -> 122585.91 | C45: =C14*Assumptions!$B$21 -> 115543.58 | D45: =D14*Assumptions!$B$21 -> 98068.361 | E45: =E14*Assumptions!$B$21 -> 93195.36 | F45: =F14*Assumptions!$B$21 -> 69539.067 | G45: =G14*Assumptions!$B$21 -> 90283.005 | H45: =H14*Assumptions!$B$21 -> 122585.91 | I45: =I14*Assumptions!$B$21 -> 117148.36 | ... M45: =M14*Assumptions!$B$21 -> 107875.6 | N45: =SUM(B45:M45) -> 1184616.7
A46: Information & Telecommunications Systems (IT&S) | B46: =B14*Assumptions!$B$22 -> 20430.984 | C46: =C14*Assumptions!$B$22 -> 19257.264 | D46: =D14*Assumptions!$B$22 -> 16344.727 | E46: =E14*Assumptions!$B$22 -> 15532.56 | F46: =F14*Assumptions!$B$22 -> 11589.845 | G46: =G14*Assumptions!$B$22 -> 15047.167 | H46: =H14*Assumptions!$B$22 -> 20430.984 | I46: =I14*Assumptions!$B$22 -> 19524.726 | ... M46: =M14*Assumptions!$B$22 -> 17979.266 | N46: =SUM(B46:M46) -> 197436.11
A47: Sales & Marketing (S&M) | B47: =B14*Assumptions!$B$23 -> 122585.91 | C47: =C14*Assumptions!$B$23 -> 115543.58 | D47: =D14*Assumptions!$B$23 -> 98068.361 | E47: =E14*Assumptions!$B$23 -> 93195.36 | F47: =F14*Assumptions!$B$23 -> 69539.067 | G47: =G14*Assumptions!$B$23 -> 90283.005 | H47: =H14*Assumptions!$B$23 -> 122585.91 | I47: =I14*Assumptions!$B$23 -> 117148.36 | ... M47: =M14*Assumptions!$B$23 -> 107875.6 | N47: =SUM(B47:M47) -> 1184616.7
...

Sheet Scenario Comparison
A1: Scenario 1 – Impact vs Baseline
A2: Changed assumptions only | G2: Annual cost change vs Baseline
A3: Assumption | B3: Baseline | C3: Scenario 1 | D3: Change | E3: Basis | G3: Cost line | H3: Baseline | I3: Scenario 1
A4: Rooms Commissions / Rooms Revenue | B4: 0.03 | C4: =Assumptions!B14 -> 0.01 | D4: =C4-B4 -> -0.02 | E4: % of Rooms Revenue | G4: Rooms Commissions | H4: 263248.15 | I4: ='Pro Forma P&L'!N18 -> 87749.383
A5: S&M / Total Operating Revenue | B5: 0.08 | C5: =Assumptions!B23 -> 0.09 | D5: =C5-B5 -> 0.01 | E5: % of Total Operating Revenue | G5: Sales & Marketing | H5: 1052992.6 | I5: ='Pro Forma P&L'!N47 -> 1184616.7
A7: Annual financial impact vs Baseline
A8: Metric | B8: Baseline | C8: Scenario 1 | D8: Δ vs Base | E8: % Change
A9: Rooms Commissions | B9: 263248.15 | C9: ='Pro Forma P&L'!N18 -> 87749.383 | D9: =C9-B9 -> -175498.77 | E9: =IF(B9=0,"",D9/ABS(B9)) -> -0.66666667
A10: Rooms Department Profit | B10: 6756702.5 | C10: ='Pro Forma P&L'!N21 -> 6932201.3 | D10: =C10-B10 -> 175498.77 | E10: =IF(B10=0,"",D10/ABS(B10)) -> 0.025974026
A11: Sales & Marketing (S&M) | B11: 1052992.6 | C11: ='Pro Forma P&L'!N47 -> 1184616.7 | D11: =C11-B11 -> 131624.08 | E11: =IF(B11=0,"",D11/ABS(B11)) -> 0.125
A12: Total Departmental Expenses | B12: 5286900.4 | C12: ='Pro Forma P&L'!N40 -> 5111401.6 | D12: =C12-B12 -> -175498.77 | E12: =IF(B12=0,"",D12/ABS(B12)) -> -0.033195021
A13: Total Undistributed Operating Expenses | B13: 3751286.1 | C13: ='Pro Forma P&L'!N50 -> 3882910.2 | D13: =C13-B13 -> 131624.08 | E13: =IF(B13=0,"",D13/ABS(B13)) -> 0.035087719
A14: Gross Operating Profit (GOP) | B14: 4124221 | C14: ='Pro Forma P&L'!N52 -> 4168095.7 | D14: =C14-B14 -> 43874.692 | E14: =IF(B14=0,"",D14/ABS(B14)) -> 0.010638298
A15: GOP Margin | B15: 0.31333333 | C15: ='Pro Forma P&L'!N53 -> 0.31666667 | D15: =C15-B15 -> 0.0033333333
A16: Incentive Management Fee | B16: 329937.68 | C16: ='Pro Forma P&L'!N57 -> 333447.66 | D16: =C16-B16 -> 3509.9753 | E16: =IF(B16=0,"",D16/ABS(B16)) -> 0.010638298
A17: NOI | B17: 3004538.9 | C17: ='Pro Forma P&L'!N60 -> 3044903.6 | D17: =C17-B17 -> 40364.716 | E17: =IF(B17=0,"",D17/ABS(B17)) -> 0.013434579
A18: NOI Margin | B18: 0.22826667 | C18: ='Pro Forma P&L'!N61 -> 0.23133333 | D18: =C18-B18 -> 0.0030666667
A21: Monthly profit impact vs Baseline
A22: Month | B22: Baseline GOP | C22: Scenario 1 GOP | D22: Δ GOP | E22: Baseline NOI | F22: Scenario 1 NOI | G22: Δ NOI
A23: Jan | B23: 426780.56 | C23: ='Pro Forma P&L'!B52 -> 431320.78 | D23: =C23-B23 -> 4540.2188 | E23: 310914.18 | F23: ='Pro Forma P&L'!B60 -> 315091.18 | G23: =F23-E23 -> 4177.0013
A24: Feb | B24: 402262.85 | C24: ='Pro Forma P&L'!C52 -> 406542.24 | D24: =C24-B24 -> 4279.392 | E24: 293052.76 | F24: ='Pro Forma P&L'!C60 -> 296989.8 | G24: =F24-E24 -> 3937.0406
A25: Mar | B25: 341423.18 | C25: ='Pro Forma P&L'!D52 -> 345055.34 | D25: =C25-B25 -> 3632.1615 | E25: 248730.42 | F25: ='Pro Forma P&L'!D60 -> 252072.01 | G25: =F25-E25 -> 3341.5886
A26: Apr | B26: 324457.92 | C26: ='Pro Forma P&L'!E52 -> 327909.6 | D26: =C26-B26 -> 3451.68 | E26: 236371.05 | F26: ='Pro Forma P&L'!E60 -> 239546.59 | G26: =F26-E26 -> 3175.5456
A27: May | B27: 242098.97 | C27: ='Pro Forma P&L'!F52 -> 244674.5 | D27: =C27-B27 -> 2575.521 | E27: 176371.68 | F27: ='Pro Forma P&L'!F60 -> 178741.16 | G27: =F27-E27 -> 2369.4793
A28: Jun | B28: 314318.61 | C28: ='Pro Forma P&L'!G52 -> 317662.42 | D28: =C28-B28 -> 3343.815 | E28: 228984.45 | F28: ='Pro Forma P&L'!G60 -> 232060.76 | G28: =F28-E28 -> 3076.3098
A29: Jul | B29: 426780.56 | C29: ='Pro Forma P&L'!H52 -> 431320.78 | D29: =C29-B29 -> 4540.2188 | E29: 310914.18 | F29: ='Pro Forma P&L'!H60 -> 315091.18 | G29: =F29-E29 -> 4177.0013
A30: Aug | B30: 407849.83 | C30: ='Pro Forma P&L'!I52 -> 412188.66 | D30: =C30-B30 -> 4338.828 | E30: 297122.94 | F30: ='Pro Forma P&L'!I60 -> 301114.66 | G30: =F30-E30 -> 3991.7218
A31: Sep | B31: 242098.97 | C31: ='Pro Forma P&L'!J52 -> 244674.5 | D31: =C31-B31 -> 2575.521 | E31: 176371.68 | F31: ='Pro Forma P&L'!J60 -> 178741.16 | G31: =F31-E31 -> 2369.4793
A32: Oct | B32: 261766.15 | C32: ='Pro Forma P&L'!K52 -> 264550.89 | D32: =C32-B32 -> 2784.7463 | E32: 190699.42 | F32: ='Pro Forma P&L'!K60 -> 193261.39 | G32: =F32-E32 -> 2561.9666
A33: Nov | B33: 358816.52 | C33: ='Pro Forma P&L'!L52 -> 362633.72 | D33: =C33-B33 -> 3817.197 | E33: 261401.65 | F33: ='Pro Forma P&L'!L60 -> 264913.47 | G33: =F33-E33 -> 3511.8212
A34: Dec | B34: 375566.89 | C34: ='Pro Forma P&L'!M52 -> 379562.29 | D34: =C34-B34 -> 3995.3925 | E34: 273604.48 | F34: ='Pro Forma P&L'!M60 -> 277280.24 | G34: =F34-E34 -> 3675.7611
